[2024-02-06T22:22:42.353+0100] {taskinstance.py:1956} INFO - Dependencies all met for dep_context=non-requeueable deps ti=<TaskInstance: Competition_dag.match_task scheduled__2024-01-07T00:00:00+00:00 [queued]>
[2024-02-06T22:22:42.366+0100] {taskinstance.py:1956} INFO - Dependencies all met for dep_context=requeueable deps ti=<TaskInstance: Competition_dag.match_task scheduled__2024-01-07T00:00:00+00:00 [queued]>
[2024-02-06T22:22:42.367+0100] {taskinstance.py:2170} INFO - Starting attempt 1 of 6
[2024-02-06T22:22:42.521+0100] {taskinstance.py:2191} INFO - Executing <Task(PythonOperator): match_task> on 2024-01-07 00:00:00+00:00
[2024-02-06T22:22:42.540+0100] {standard_task_runner.py:60} INFO - Started process 46708 to run task
[2024-02-06T22:22:42.559+0100] {standard_task_runner.py:87} INFO - Running: ['airflow', 'tasks', 'run', 'Competition_dag', 'match_task', 'scheduled__2024-01-07T00:00:00+00:00', '--job-id', '39', '--raw', '--subdir', 'DAGS_FOLDER/datalake_dag.py', '--cfg-path', '/tmp/tmpj7rud6zr']
[2024-02-06T22:22:42.564+0100] {standard_task_runner.py:88} INFO - Job 39: Subtask match_task
[2024-02-06T22:22:42.869+0100] {task_command.py:423} INFO - Running <TaskInstance: Competition_dag.match_task scheduled__2024-01-07T00:00:00+00:00 [running]> on host ubuntu.ubuntu.virtualbox.org
[2024-02-06T22:22:43.178+0100] {taskinstance.py:2480} INFO - Exporting env vars: AIRFLOW_CTX_DAG_OWNER='NOUMEN_Frech_Warren' AIRFLOW_CTX_DAG_ID='Competition_dag' AIRFLOW_CTX_TASK_ID='match_task' AIRFLOW_CTX_EXECUTION_DATE='2024-01-07T00:00:00+00:00' AIRFLOW_CTX_TRY_NUMBER='1' AIRFLOW_CTX_DAG_RUN_ID='scheduled__2024-01-07T00:00:00+00:00'
[2024-02-06T22:22:43.192+0100] {logging_mixin.py:188} INFO - helloWord
[2024-02-06T22:22:44.163+0100] {logging_mixin.py:188} INFO - Data fetch successfully
[2024-02-06T22:22:44.180+0100] {client.py:192} INFO - Instantiated <InsecureClient(url='http://localhost:9870')>.
[2024-02-06T22:22:44.188+0100] {client.py:496} INFO - Writing to '/datalake/raw/2024-01-07'.
[2024-02-06T22:22:44.196+0100] {logging_mixin.py:188} INFO - Some error occurred during writing to hdfs: HTTPConnectionPool(host='localhost', port=9870): Max retries exceeded with url: /webhdfs/v1/datalake/raw/2024-01-07?user.name=ubuntu&overwrite=True&op=CREATE (Caused by NewConnectionError('<urllib3.connection.HTTPConnection object at 0x7f68f5026500>: Failed to establish a new connection: [Errno 111] Connection refused'))
[2024-02-06T22:22:44.196+0100] {python.py:201} INFO - Done. Returned value was: None
[2024-02-06T22:22:44.216+0100] {taskinstance.py:1138} INFO - Marking task as SUCCESS. dag_id=Competition_dag, task_id=match_task, execution_date=20240107T000000, start_date=20240206T212242, end_date=20240206T212244
[2024-02-06T22:22:44.533+0100] {local_task_job_runner.py:234} INFO - Task exited with return code 0
[2024-02-06T22:22:44.642+0100] {taskinstance.py:3280} INFO - 1 downstream tasks scheduled from follow-on schedule check
