[2024-02-06T22:19:12.718+0100] {taskinstance.py:1956} INFO - Dependencies all met for dep_context=non-requeueable deps ti=<TaskInstance: Competition_dag.match_task scheduled__2024-01-04T00:00:00+00:00 [queued]>
[2024-02-06T22:19:12.729+0100] {taskinstance.py:1956} INFO - Dependencies all met for dep_context=requeueable deps ti=<TaskInstance: Competition_dag.match_task scheduled__2024-01-04T00:00:00+00:00 [queued]>
[2024-02-06T22:19:12.729+0100] {taskinstance.py:2170} INFO - Starting attempt 1 of 6
[2024-02-06T22:19:12.863+0100] {taskinstance.py:2191} INFO - Executing <Task(PythonOperator): match_task> on 2024-01-04 00:00:00+00:00
[2024-02-06T22:19:12.904+0100] {standard_task_runner.py:60} INFO - Started process 43995 to run task
[2024-02-06T22:19:12.914+0100] {standard_task_runner.py:87} INFO - Running: ['airflow', 'tasks', 'run', 'Competition_dag', 'match_task', 'scheduled__2024-01-04T00:00:00+00:00', '--job-id', '32', '--raw', '--subdir', 'DAGS_FOLDER/datalake_dag.py', '--cfg-path', '/tmp/tmp02yvvor8']
[2024-02-06T22:19:12.922+0100] {standard_task_runner.py:88} INFO - Job 32: Subtask match_task
[2024-02-06T22:19:13.201+0100] {task_command.py:423} INFO - Running <TaskInstance: Competition_dag.match_task scheduled__2024-01-04T00:00:00+00:00 [running]> on host ubuntu.ubuntu.virtualbox.org
[2024-02-06T22:19:13.593+0100] {taskinstance.py:2480} INFO - Exporting env vars: AIRFLOW_CTX_DAG_OWNER='NOUMEN_Frech_Warren' AIRFLOW_CTX_DAG_ID='Competition_dag' AIRFLOW_CTX_TASK_ID='match_task' AIRFLOW_CTX_EXECUTION_DATE='2024-01-04T00:00:00+00:00' AIRFLOW_CTX_TRY_NUMBER='1' AIRFLOW_CTX_DAG_RUN_ID='scheduled__2024-01-04T00:00:00+00:00'
[2024-02-06T22:19:13.601+0100] {logging_mixin.py:188} INFO - helloWord
[2024-02-06T22:19:14.606+0100] {logging_mixin.py:188} INFO - Data fetch successfully
[2024-02-06T22:19:14.641+0100] {client.py:192} INFO - Instantiated <InsecureClient(url='http://localhost:9870')>.
[2024-02-06T22:19:14.644+0100] {client.py:496} INFO - Writing to '/datalake/raw/2024-01-04'.
[2024-02-06T22:19:14.651+0100] {logging_mixin.py:188} INFO - Some error occurred during writing to hdfs: HTTPConnectionPool(host='localhost', port=9870): Max retries exceeded with url: /webhdfs/v1/datalake/raw/2024-01-04?user.name=ubuntu&overwrite=True&op=CREATE (Caused by NewConnectionError('<urllib3.connection.HTTPConnection object at 0x7ff0ae6724d0>: Failed to establish a new connection: [Errno 111] Connection refused'))
[2024-02-06T22:19:14.651+0100] {python.py:201} INFO - Done. Returned value was: None
[2024-02-06T22:19:14.660+0100] {taskinstance.py:1138} INFO - Marking task as SUCCESS. dag_id=Competition_dag, task_id=match_task, execution_date=20240104T000000, start_date=20240206T211912, end_date=20240206T211914
[2024-02-06T22:19:14.813+0100] {local_task_job_runner.py:234} INFO - Task exited with return code 0
[2024-02-06T22:19:14.910+0100] {taskinstance.py:3280} INFO - 1 downstream tasks scheduled from follow-on schedule check
[2024-02-06T22:33:59.910+0100] {taskinstance.py:1956} INFO - Dependencies all met for dep_context=non-requeueable deps ti=<TaskInstance: Competition_dag.match_task scheduled__2024-01-04T00:00:00+00:00 [queued]>
[2024-02-06T22:33:59.987+0100] {taskinstance.py:1956} INFO - Dependencies all met for dep_context=requeueable deps ti=<TaskInstance: Competition_dag.match_task scheduled__2024-01-04T00:00:00+00:00 [queued]>
[2024-02-06T22:33:59.987+0100] {taskinstance.py:2170} INFO - Starting attempt 1 of 6
[2024-02-06T22:34:00.125+0100] {taskinstance.py:2191} INFO - Executing <Task(PythonOperator): match_task> on 2024-01-04 00:00:00+00:00
[2024-02-06T22:34:00.145+0100] {standard_task_runner.py:60} INFO - Started process 54758 to run task
[2024-02-06T22:34:00.171+0100] {standard_task_runner.py:87} INFO - Running: ['airflow', 'tasks', 'run', 'Competition_dag', 'match_task', 'scheduled__2024-01-04T00:00:00+00:00', '--job-id', '35', '--raw', '--subdir', 'DAGS_FOLDER/datalake_dag.py', '--cfg-path', '/tmp/tmpz058m2ot']
[2024-02-06T22:34:00.178+0100] {standard_task_runner.py:88} INFO - Job 35: Subtask match_task
[2024-02-06T22:34:00.508+0100] {task_command.py:423} INFO - Running <TaskInstance: Competition_dag.match_task scheduled__2024-01-04T00:00:00+00:00 [running]> on host ubuntu.ubuntu.virtualbox.org
[2024-02-06T22:34:00.835+0100] {taskinstance.py:2480} INFO - Exporting env vars: AIRFLOW_CTX_DAG_OWNER='NOUMEN_Frech_Warren' AIRFLOW_CTX_DAG_ID='Competition_dag' AIRFLOW_CTX_TASK_ID='match_task' AIRFLOW_CTX_EXECUTION_DATE='2024-01-04T00:00:00+00:00' AIRFLOW_CTX_TRY_NUMBER='1' AIRFLOW_CTX_DAG_RUN_ID='scheduled__2024-01-04T00:00:00+00:00'
[2024-02-06T22:34:00.868+0100] {logging_mixin.py:188} INFO - helloWord
[2024-02-06T22:34:02.093+0100] {logging_mixin.py:188} INFO - Data fetch successfully
[2024-02-06T22:34:02.105+0100] {client.py:192} INFO - Instantiated <InsecureClient(url='http://localhost:9870')>.
[2024-02-06T22:34:02.111+0100] {client.py:496} INFO - Writing to '/datalake/raw/2024-01-04'.
[2024-02-06T22:34:02.130+0100] {logging_mixin.py:188} INFO - Some error occurred during writing to hdfs: HTTPConnectionPool(host='localhost', port=9870): Max retries exceeded with url: /webhdfs/v1/datalake/raw/2024-01-04?user.name=ubuntu&overwrite=True&op=CREATE (Caused by NewConnectionError('<urllib3.connection.HTTPConnection object at 0x7fd45658a4a0>: Failed to establish a new connection: [Errno 111] Connection refused'))
[2024-02-06T22:34:02.135+0100] {python.py:201} INFO - Done. Returned value was: None
[2024-02-06T22:34:02.151+0100] {taskinstance.py:1138} INFO - Marking task as SUCCESS. dag_id=Competition_dag, task_id=match_task, execution_date=20240104T000000, start_date=20240206T213359, end_date=20240206T213402
[2024-02-06T22:34:02.371+0100] {local_task_job_runner.py:234} INFO - Task exited with return code 0
[2024-02-06T22:34:02.432+0100] {taskinstance.py:3280} INFO - 1 downstream tasks scheduled from follow-on schedule check
